Workbook

Sheet Executive Summary
A1: Nxance — AI-Powered Investment Intelligence Platform | Investor Financial Summary
A4: Recommended Ask | D4: Runway | G4: Exit Headcount Capacity | J4: Exit Monthly Payroll / Team Cost | M4: Exit Monthly Cash Use
A5: ='Monthly Burn'!B30 -> 12.487034 | D5: =Assumptions!B4 -> 18 | G5: =Assumptions!B7 -> 40 | J5: ='Hiring Plan'!B34 -> 37.85 | M5: ='Monthly Burn'!L21 -> 76.914496
A8: 18M Operating Burn | D8: Contingency | G8: Gross 18M Subscription Revenue | J8: Revenue Coverage of Operating Burn | M8: Planning Pre-Money
A9: ='Monthly Burn'!B26/100 -> 11.104495 | D9: ='Monthly Burn'!B28/100 -> 1.3325394 | G9: ='Business model'!D16/100 -> 0.7605 | J9: ='Business model'!D18 -> 0.068485782 | M9: =valuation!B7 -> 49.948136
A12: Funding Thesis | H12: Investor Decision Gates
A13: The current management budget is materially larger than the earlier base case because it now carries four founder draws, a broad in-house technology and investment-research stack, a rising marketing budget, Bengaluru operating costs and a regulated-fintech compliance path. The investor ask is therefore shown as gross execution capital, with subscription revenue kept as upside rather than used to reduce runway. | H13: Gate | I13: Timing | J13: Evidence Required | K13: Capital Decision | L13: Linked tranche | M13: Amount released
H14: MBP / Alpha | I14: M1–3 | J14: Working portfolio analysis + user validation | K14: Continue core product build | L14: Tranche 1 | M14: ='Funding Tranches'!D4 -> 274.14
H15: Regulatory / Security | I15: M4–6 | J15: Regulatory route, controls, VAPT and data plan | K15: Advance regulated beta budget | L15: Tranche 2 | M15: ='Funding Tranches'!D5 -> 527.24
H16: Paid Beta | I16: M7–9 | J16: Paid conversion, repeat use and support data | K16: Release public-launch spend | L16: Tranche 3 | M16: ='Funding Tranches'!D6 -> 447.62
H17: Public V1 / Scale | I17: M10–18 | J17: Recurring revenue, institutional pilots and security maturity | K17: Prepare next financing / strategic path
A19: Key Model Read-Out
A20: Metric | B20: Value | C20: Unit | D20: Interpretation
A21: Peak monthly cash use | B21: ='Monthly Burn'!B32 -> 76.914496 | C21: ₹ lakh | D21: Month 18 is currently the peak
A22: Average monthly cash use | B22: ='Monthly Burn'!B31 -> 61.969414 | C22: ₹ lakh | D22: Before contingency
A23: Refundable / restricted cash | B23: ='Monthly Burn'!B27 -> 5 | C23: ₹ lakh | D23: Shown separately from operating burn
A24: Target round dilution | B24: =valuation!B6 -> 0.2 | C24: % | D24: Planning case only

Sheet Budgeting
A1: Nxance — 18-Month Management Budget
A3: Category | B3: Line Item | C3: Amount (₹ lakh / month or one-time) | D3: Milestone Trigger | E3: Start Mo. | F3: Type | G3: Growth / Ramp Input | H3: 1 | I3: 2 | J3: 3 | K3: 4 | L3: 5 | M3: 6 | N3: 7 | O3: 8 | P3: 9 | Q3: 10 | R3: 11 | S3: 12 | T3: 13 | U3: 14 | V3: 15 | W3: 16 | X3: 17 | Y3: 18 | Z3: Line Total (₹ lakh) | AA3: Section Total (₹ lakh)
A4: FOUNDER
B5: Abhishek | C5: 1.25 | D5: Day 1 — company formation | E5: 1 | F5: Recurring | G5: 0 | H5: 1.25 | I5: 1.25 | J5: 1.25 | K5: 1.25 | L5: 1.25 | M5: 1.25 | N5: 1.25 | O5: 1.25 | P5: 1.25 | Q5: 1.25 | R5: 1.25 | S5: 1.25 | T5: 1.25 | U5: 1.25 | V5: 1.25 | W5: 1.25 | X5: 1.25 | Y5: 1.25 | Z5: =SUM(H5:Y5) -> 22.5
B6: Bhaskar | C6: 1.25 | D6: Day 1 — company formation | E6: 1 | F6: Recurring | G6: 0 | H6: 1.25 | I6: 1.25 | J6: 1.25 | K6: 1.25 | L6: 1.25 | M6: 1.25 | N6: 1.25 | O6: 1.25 | P6: 1.25 | Q6: 1.25 | R6: 1.25 | S6: 1.25 | T6: 1.25 | U6: 1.25 | V6: 1.25 | W6: 1.25 | X6: 1.25 | Y6: 1.25 | Z6: =SUM(H6:Y6) -> 22.5
B7: Deepesh | C7: 1.25 | D7: Day 1 — company formation | E7: 1 | F7: Recurring | G7: 0 | H7: 1.25 | I7: 1.25 | J7: 1.25 | K7: 1.25 | L7: 1.25 | M7: 1.25 | N7: 1.25 | O7: 1.25 | P7: 1.25 | Q7: 1.25 | R7: 1.25 | S7: 1.25 | T7: 1.25 | U7: 1.25 | V7: 1.25 | W7: 1.25 | X7: 1.25 | Y7: 1.25 | Z7: =SUM(H7:Y7) -> 22.5
B8: Raghav | C8: 1.5 | D8: Day 1 — company formation | E8: 1 | F8: Recurring | G8: 0 | H8: 1.5 | I8: 1.5 | J8: 1.5 | K8: 1.5 | L8: 1.5 | M8: 1.5 | N8: 1.5 | O8: 1.5 | P8: 1.5 | Q8: 1.5 | R8: 1.5 | S8: 1.5 | T8: 1.5 | U8: 1.5 | V8: 1.5 | W8: 1.5 | X8: 1.5 | Y8: 1.5 | Z8: =SUM(H8:Y8) -> 27
AA9: =SUM(Z5:Z8) -> 94.5
A10: INSURANCE
B11: D&O (Directors & Officers) | C11: 0.1 | D11: Entity registered + funding closed | E11: 3 | F11: Recurring | G11: 0 | H11: =IF($F11="Recurring",IF(H$2>=$E11,$C11*(1+$G11)^FLOOR((H$2-$E11)/3,1),0),IF(H$2=$E11,$C11,0)) -> 0 | I11: =IF($F11="Recurring",IF(I$2>=$E11,$C11*(1+$G11)^FLOOR((I$2-$E11)/3,1),0),IF(I$2=$E11,$C11,0)) -> 0 | J11: 0.1 | K11: 0.1 | L11: 0.1 | M11: 0.1 | N11: 0.1 | O11: 0.1 | P11: 0.1 | Q11: 0.1 | R11: 0.1 | S11: 0.1 | T11: 0.1 | U11: 0.1 | V11: 0.1 | W11: 0.1 | X11: 0.1 | Y11: 0.1 | Z11: =SUM(H11:Y11) -> 1.6
B12: Cyber liability | C12: 0.1 | D12: Entity registered + funding closed | E12: 3 | F12: Recurring | G12: 0 | H12: =IF($F12="Recurring",IF(H$2>=$E12,$C12*(1+$G12)^FLOOR((H$2-$E12)/3,1),0),IF(H$2=$E12,$C12,0)) -> 0 | I12: =IF($F12="Recurring",IF(I$2>=$E12,$C12*(1+$G12)^FLOOR((I$2-$E12)/3,1),0),IF(I$2=$E12,$C12,0)) -> 0 | J12: 0.1 | K12: 0.1 | L12: 0.1 | M12: 0.1 | N12: 0.1 | O12: 0.1 | P12: 0.1 | Q12: 0.1 | R12: 0.1 | S12: 0.1 | T12: 0.1 | U12: 0.1 | V12: 0.1 | W12: 0.1 | X12: 0.1 | Y12: 0.1 | Z12: =SUM(H12:Y12) -> 1.6
B13: General liability insurance | C13: 0.1 | D13: Entity registered + funding closed | E13: 3 | F13: Recurring | G13: 0 | H13: =IF($F13="Recurring",IF(H$2>=$E13,$C13*(1+$G13)^FLOOR((H$2-$E13)/3,1),0),IF(H$2=$E13,$C13,0)) -> 0 | I13: =IF($F13="Recurring",IF(I$2>=$E13,$C13*(1+$G13)^FLOOR((I$2-$E13)/3,1),0),IF(I$2=$E13,$C13,0)) -> 0 | J13: 0.1 | K13: 0.1 | L13: 0.1 | M13: 0.1 | N13: 0.1 | O13: 0.1 | P13: 0.1 | Q13: 0.1 | R13: 0.1 | S13: 0.1 | T13: 0.1 | U13: 0.1 | V13: 0.1 | W13: 0.1 | X13: 0.1 | Y13: 0.1 | Z13: =SUM(H13:Y13) -> 1.6
AA14: =SUM(Z11:Z13) -> 4.8
A15: TECH
B16: Server & cloud infrastructure | C16: 1 | D16: Day 1 — scales with active users | E16: 1 | F16: Recurring | G16: 0.12 | H16: 1 | I16: 1 | J16: 1 | K16: 1.12 | L16: 1.12 | M16: 1.12 | N16: 1.25 | O16: 1.25 | P16: 1.25 | Q16: 1.4 | R16: 1.4 | S16: 1.4 | T16: 1.57 | U16: 1.57 | V16: 1.57 | W16: 1.76 | X16: 1.76 | Y16: 1.76 | Z16: =SUM(H16:Y16) -> 24.3
B17: QA/Test Engineer | C17: 1 | D17: MBP feature-complete, entering test phase | E17: 5 | F17: Recurring | G17: 0 | H17: 0 | I17: 0 | J17: 0 | K17: 0 | L17: 1 | M17: 1 | N17: 1 | O17: 1 | P17: 1 | Q17: 1 | R17: 1 | S17: 1 | T17: 1 | U17: 1 | V17: 1 | W17: 1 | X17: 1 | Y17: 1 | Z17: =SUM(H17:Y17) -> 14
B18: Quant Analyst — Health Check engine | C18: 1.5 | D18: Beta phase begins (post-MBP validation) | E18: 1 | F18: Recurring | G18: 0 | H18: 1.5 | I18: 1.5 | J18: 1.5 | K18: 1.5 | L18: 1.5 | M18: 1.5 | N18: 1.5 | O18: 1.5 | P18: 1.5 | Q18: 1.5 | R18: 1.5 | S18: 1.5 | T18: 1.5 | U18: 1.5 | V18: 1.5 | W18: 1.5 | X18: 1.5 | Y18: 1.5 | Z18: =SUM(H18:Y18) -> 27
B19: Quant Analyst — Construction engine | C19: 1.5 | D19: Beta phase begins (post-MBP validation) | E19: 1 | F19: Recurring | G19: 0 | H19: 1.5 | I19: 1.5 | J19: 1.5 | K19: 1.5 | L19: 1.5 | M19: 1.5 | N19: 1.5 | O19: 1.5 | P19: 1.5 | Q19: 1.5 | R19: 1.5 | S19: 1.5 | T19: 1.5 | U19: 1.5 | V19: 1.5 | W19: 1.5 | X19: 1.5 | Y19: 1.5 | Z19: =SUM(H19:Y19) -> 27
B20: AI & LLM | C20: 2 | D20: MBP build starts | E20: 2 | F20: Recurring | G20: 0 | H20: =IF($F20="Recurring",IF(H$2>=$E20,$C20*(1+$G20)^FLOOR((H$2-$E20)/3,1),0),IF(H$2=$E20,$C20,0)) -> 0 | I20: 2 | J20: 2 | K20: 2 | L20: 2 | M20: 2 | N20: 2 | O20: 2 | P20: 2 | Q20: 2 | R20: 2 | S20: 2 | T20: 2 | U20: 2 | V20: 2 | W20: 2 | X20: 2 | Y20: 2 | Z20: =SUM(H20:Y20) -> 34
B21: AI massive compute (training/fine-tune build-out) | C21: 2 | D21: Phase 2 roadmap — after Beta traction proven | E21: 6 | F21: Recurring | G21: 0.15 | H21: =IF($F21="Recurring",IF(H$2>=$E21,$C21*(1+$G21)^FLOOR((H$2-$E21)/3,1),0),IF(H$2=$E21,$C21,0)) -> 0 | I21: =IF($F21="Recurring",IF(I$2>=$E21,$C21*(1+$G21)^FLOOR((I$2-$E21)/3,1),0),IF(I$2=$E21,$C21,0)) -> 0 | J21: =IF($F21="Recurring",IF(J$2>=$E21,$C21*(1+$G21)^FLOOR((J$2-$E21)/3,1),0),IF(J$2=$E21,$C21,0)) -> 0 | K21: =IF($F21="Recurring",IF(K$2>=$E21,$C21*(1+$G21)^FLOOR((K$2-$E21)/3,1),0),IF(K$2=$E21,$C21,0)) -> 0 | L21: =IF($F21="Recurring",IF(L$2>=$E21,$C21*(1+$G21)^FLOOR((L$2-$E21)/3,1),0),IF(L$2=$E21,$C21,0)) -> 0 | M21: 2 | N21: 2 | O21: 2 | P21: 2 | Q21: 2.3 | R21: 2.3 | S21: 2.3 | T21: 2.65 | U21: 2.65 | V21: 2.65 | W21: 3.05 | X21: 3.05 | Y21: 3.05 | Z21: =SUM(H21:Y21) -> 32
B22: API | C22: 2 | D22: MBP build starts | E22: 2 | F22: Recurring | G22: 0 | H22: =IF($F22="Recurring",IF(H$2>=$E22,$C22*(1+$G22)^FLOOR((H$2-$E22)/3,1),0),IF(H$2=$E22,$C22,0)) -> 0 | I22: 2 | J22: 2 | K22: 2 | L22: 2 | M22: 2 | N22: 2 | O22: 2 | P22: 2 | Q22: 2 | R22: 2 | S22: 2 | T22: 2 | U22: 2 | V22: 2 | W22: 2 | X22: 2 | Y22: 2 | Z22: =SUM(H22:Y22) -> 34
B23: Backend Engineer 1 | C23: 1 | D23: MBP build starts | E23: 2 | F23: Recurring | G23: 0 | H23: =IF($F23="Recurring",IF(H$2>=$E23,$C23*(1+$G23)^FLOOR((H$2-$E23)/3,1),0),IF(H$2=$E23,$C23,0)) -> 0 | I23: 1 | J23: 1 | K23: 1 | L23: 1 | M23: 1 | N23: 1 | O23: 1 | P23: 1 | Q23: 1 | R23: 1 | S23: 1 | T23: 1 | U23: 1 | V23: 1 | W23: 1 | X23: 1 | Y23: 1 | Z23: =SUM(H23:Y23) -> 17
B24: Backend Engineer 2 | C24: 1 | D24: Beta phase — scaling build capacity | E24: 5 | F24: Recurring | G24: 0 | H24: =IF($F24="Recurring",IF(H$2>=$E24,$C24*(1+$G24)^FLOOR((H$2-$E24)/3,1),0),IF(H$2=$E24,$C24,0)) -> 0 | I24: =IF($F24="Recurring",IF(I$2>=$E24,$C24*(1+$G24)^FLOOR((I$2-$E24)/3,1),0),IF(I$2=$E24,$C24,0)) -> 0 | J24: =IF($F24="Recurring",IF(J$2>=$E24,$C24*(1+$G24)^FLOOR((J$2-$E24)/3,1),0),IF(J$2=$E24,$C24,0)) -> 0 | K24: =IF($F24="Recurring",IF(K$2>=$E24,$C24*(1+$G24)^FLOOR((K$2-$E24)/3,1),0),IF(K$2=$E24,$C24,0)) -> 0 | L24: 1 | M24: 1 | N24: 1 | O24: 1 | P24: 1 | Q24: 1 | R24: 1 | S24: 1 | T24: 1 | U24: 1 | V24: 1 | W24: 1 | X24: 1 | Y24: 1 | Z24: =SUM(H24:Y24) -> 14
B25: Frontend Engineer | C25: 1 | D25: MBP build starts | E25: 2 | F25: Recurring | G25: 0 | H25: 0 | I25: 1 | J25: 1 | K25: 1 | L25: 1 | M25: 1 | N25: 1 | O25: 1 | P25: 1 | Q25: 1 | R25: 1 | S25: 1 | T25: 1 | U25: 1 | V25: 1 | W25: 1 | X25: 1 | Y25: 1 | Z25: =SUM(H25:Y25) -> 17
B26: ML Engineer | C26: 1 | D26: Phase 1 roadmap — scenario sandbox work begins | E26: 1 | F26: Recurring | G26: 0 | H26: 1 | I26: 1 | J26: 1 | K26: 1 | L26: 1 | M26: 1 | N26: 1 | O26: 1 | P26: 1 | Q26: 1 | R26: 1 | S26: 1 | T26: 1 | U26: 1 | V26: 1 | W26: 1 | X26: 1 | Y26: 1 | Z26: =SUM(H26:Y26) -> 18
B27: AI Engineer | C27: 1 | D27: Phase 1 roadmap — NxanceLM build-out | E27: 1 | F27: Recurring | G27: 0 | H27: 1 | I27: 1 | J27: 1 | K27: 1 | L27: 1 | M27: 1 | N27: 1 | O27: 1 | P27: 1 | Q27: 1 | R27: 1 | S27: 1 | T27: 1 | U27: 1 | V27: 1 | W27: 1 | X27: 1 | Y27: 1 | Z27: =SUM(H27:Y27) -> 18
B28: Cybersecurity Engineer & Deveops | C28: 1 | D28: Ahead of AI compute build-out / RIA-grade data security | E28: 5 | F28: Recurring | G28: 0 | H28: =IF($F28="Recurring",IF(H$2>=$E28,$C28*(1+$G28)^FLOOR((H$2-$E28)/3,1),0),IF(H$2=$E28,$C28,0)) -> 0 | I28: =IF($F28="Recurring",IF(I$2>=$E28,$C28*(1+$G28)^FLOOR((I$2-$E28)/3,1),0),IF(I$2=$E28,$C28,0)) -> 0 | J28: =IF($F28="Recurring",IF(J$2>=$E28,$C28*(1+$G28)^FLOOR((J$2-$E28)/3,1),0),IF(J$2=$E28,$C28,0)) -> 0 | K28: =IF($F28="Recurring",IF(K$2>=$E28,$C28*(1+$G28)^FLOOR((K$2-$E28)/3,1),0),IF(K$2=$E28,$C28,0)) -> 0 | L28: 1 | M28: 1 | N28: 1 | O28: 1 | P28: 1 | Q28: 1 | R28: 1 | S28: 1 | T28: 1 | U28: 1 | V28: 1 | W28: 1 | X28: 1 | Y28: 1 | Z28: =SUM(H28:Y28) -> 14
B29: Miscellaneous | C29: 2 | D29: Day 1 | E29: 1 | F29: Recurring | G29: 0 | H29: 2 | I29: 2 | J29: 2 | K29: 2 | L29: 2 | M29: 2 | N29: 2 | O29: 2 | P29: 2 | Q29: 2 | R29: 2 | S29: 2 | T29: 2 | U29: 2 | V29: 2 | W29: 2 | X29: 2 | Y29: 2 | Z29: =SUM(H29:Y29) -> 36
B30: Tech Research | C30: 1 | D30: Beta phase | E30: 10 | F30: Recurring | G30: 0 | H30: =IF($F30="Recurring",IF(H$2>=$E30,$C30*(1+$G30)^FLOOR((H$2-$E30)/3,1),0),IF(H$2=$E30,$C30,0)) -> 0 | I30: =IF($F30="Recurring",IF(I$2>=$E30,$C30*(1+$G30)^FLOOR((I$2-$E30)/3,1),0),IF(I$2=$E30,$C30,0)) -> 0 | J30: =IF($F30="Recurring",IF(J$2>=$E30,$C30*(1+$G30)^FLOOR((J$2-$E30)/3,1),0),IF(J$2=$E30,$C30,0)) -> 0 | K30: =IF($F30="Recurring",IF(K$2>=$E30,$C30*(1+$G30)^FLOOR((K$2-$E30)/3,1),0),IF(K$2=$E30,$C30,0)) -> 0 | L30: 0 | M30: 0 | N30: 0 | O30: 0 | P30: 1 | Q30: 1 | R30: 1 | S30: 1 | T30: 1 | U30: 1 | V30: 1 | W30: 1 | X30: 1 | Y30: 1 | Z30: =SUM(H30:Y30) -> 10
B31: Dev tools/licenses | C31: 0.5 | D31: Day 1 | E31: 1 | F31: Recurring | G31: 0 | H31: 0.5 | I31: 0.5 | J31: 0.5 | K31: 0.5 | L31: 0.5 | M31: 0.5 | N31: 0.5 | O31: 0.5 | P31: 0.5 | Q31: 0.5 | R31: 0.5 | S31: 0.5 | T31: 0.5 | U31: 0.5 | V31: 0.5 | W31: 0.5 | X31: 0.5 | Y31: 0.5 | Z31: =SUM(H31:Y31) -> 9
AA33: =SUM(Z16:Z31) -> 345.3
A34: INVESTMENT & RESEARCH
B35: Trader (quant + technical + fundamental ) | C35: 2 | D35: Post-RIA registration, execution-adjacent features approach | E35: 9 | F35: Recurring | G35: 0 | H35: =IF($F35="Recurring",IF(H$2>=$E35,$C35*(1+$G35)^FLOOR((H$2-$E35)/3,1),0),IF(H$2=$E35,$C35,0)) -> 0 | I35: =IF($F35="Recurring",IF(I$2>=$E35,$C35*(1+$G35)^FLOOR((I$2-$E35)/3,1),0),IF(I$2=$E35,$C35,0)) -> 0 | J35: =IF($F35="Recurring",IF(J$2>=$E35,$C35*(1+$G35)^FLOOR((J$2-$E35)/3,1),0),IF(J$2=$E35,$C35,0)) -> 0 | K35: =IF($F35="Recurring",IF(K$2>=$E35,$C35*(1+$G35)^FLOOR((K$2-$E35)/3,1),0),IF(K$2=$E35,$C35,0)) -> 0 | L35: =IF($F35="Recurring",IF(L$2>=$E35,$C35*(1+$G35)^FLOOR((L$2-$E35)/3,1),0),IF(L$2=$E35,$C35,0)) -> 0 | M35: =IF($F35="Recurring",IF(M$2>=$E35,$C35*(1+$G35)^FLOOR((M$2-$E35)/3,1),0),IF(M$2=$E35,$C35,0)) -> 0 | N35: =IF($F35="Recurring",IF(N$2>=$E35,$C35*(1+$G35)^FLOOR((N$2-$E35)/3,1),0),IF(N$2=$E35,$C35,0)) -> 0 | O35: =IF($F35="Recurring",IF(O$2>=$E35,$C35*(1+$G35)^FLOOR((O$2-$E35)/3,1),0),IF(O$2=$E35,$C35,0)) -> 0 | P35: 2 | Q35: 2 | R35: 2 | S35: 2 | T35: 2 | U35: 2 | V35: 2 | W35: 2 | X35: 2 | Y35: 2 | Z35: =SUM(H35:Y35) -> 20
B36: Portfolio Management | C36: 3 | D36: Phase 1 — first paying users need ongoing oversight | E36: 3 | F36: Recurring | G36: 0 | H36: =IF($F36="Recurring",IF(H$2>=$E36,$C36*(1+$G36)^FLOOR((H$2-$E36)/3,1),0),IF(H$2=$E36,$C36,0)) -> 0 | I36: =IF($F36="Recurring",IF(I$2>=$E36,$C36*(1+$G36)^FLOOR((I$2-$E36)/3,1),0),IF(I$2=$E36,$C36,0)) -> 0 | J36: 3 | K36: 3 | L36: 3 | M36: 3 | N36: 3 | O36: 3 | P36: 3 | Q36: 3 | R36: 3 | S36: 3 | T36: 3 | U36: 3 | V36: 3 | W36: 3 | X36: 3 | Y36: 3 | Z36: =SUM(H36:Y36) -> 48
B37: Research/Analysis | C37: 3 | D37: Beta phase | E37: 3 | F37: Recurring | G37: 0 | H37: =IF($F37="Recurring",IF(H$2>=$E37,$C37*(1+$G37)^FLOOR((H$2-$E37)/3,1),0),IF(H$2=$E37,$C37,0)) -> 0 | I37: =IF($F37="Recurring",IF(I$2>=$E37,$C37*(1+$G37)^FLOOR((I$2-$E37)/3,1),0),IF(I$2=$E37,$C37,0)) -> 0 | J37: 3 | K37: 3 | L37: 3 | M37: 3 | N37: 3 | O37: 3 | P37: 3 | Q37: 3 | R37: 3 | S37: 3 | T37: 3 | U37: 3 | V37: 3 | W37: 3 | X37: 3 | Y37: 3 | Z37: =SUM(H37:Y37) -> 48
B38: Risk analyst | C38: 2 | D38: Beta phase | E38: 5 | F38: Recurring | G38: 0 | H38: =IF($F38="Recurring",IF(H$2>=$E38,$C38*(1+$G38)^FLOOR((H$2-$E38)/3,1),0),IF(H$2=$E38,$C38,0)) -> 0 | I38: =IF($F38="Recurring",IF(I$2>=$E38,$C38*(1+$G38)^FLOOR((I$2-$E38)/3,1),0),IF(I$2=$E38,$C38,0)) -> 0 | J38: =IF($F38="Recurring",IF(J$2>=$E38,$C38*(1+$G38)^FLOOR((J$2-$E38)/3,1),0),IF(J$2=$E38,$C38,0)) -> 0 | K38: =IF($F38="Recurring",IF(K$2>=$E38,$C38*(1+$G38)^FLOOR((K$2-$E38)/3,1),0),IF(K$2=$E38,$C38,0)) -> 0 | L38: 2 | M38: 2 | N38: 2 | O38: 2 | P38: 2 | Q38: 2 | R38: 2 | S38: 2 | T38: 2 | U38: 2 | V38: 2 | W38: 2 | X38: 2 | Y38: 2 | Z38: =SUM(H38:Y38) -> 28
B39: Private market analyst | C39: 2 | D39: Phase 1 roadmap expansion | E39: 3 | F39: Recurring | G39: 0 | H39: =IF($F39="Recurring",IF(H$2>=$E39,$C39*(1+$G39)^FLOOR((H$2-$E39)/3,1),0),IF(H$2=$E39,$C39,0)) -> 0 | I39: =IF($F39="Recurring",IF(I$2>=$E39,$C39*(1+$G39)^FLOOR((I$2-$E39)/3,1),0),IF(I$2=$E39,$C39,0)) -> 0 | J39: 2 | K39: 2 | L39: 2 | M39: 2 | N39: 2 | O39: 2 | P39: 2 | Q39: 2 | R39: 2 | S39: 2 | T39: 2 | U39: 2 | V39: 2 | W39: 2 | X39: 2 | Y39: 2 | Z39: =SUM(H39:Y39) -> 32
A40: Freelancer & Consultant | B40: Tax aspect | C40: 1 | D40: RIA registration complete, product live | E40: 9 | F40: Recurring | G40: 0 | H40: =IF($F40="Recurring",IF(H$2>=$E40,$C40*(1+$G40)^FLOOR((H$2-$E40)/3,1),0),IF(H$2=$E40,$C40,0)) -> 0 | I40: =IF($F40="Recurring",IF(I$2>=$E40,$C40*(1+$G40)^FLOOR((I$2-$E40)/3,1),0),IF(I$2=$E40,$C40,0)) -> 0 | J40: =IF($F40="Recurring",IF(J$2>=$E40,$C40*(1+$G40)^FLOOR((J$2-$E40)/3,1),0),IF(J$2=$E40,$C40,0)) -> 0 | K40: =IF($F40="Recurring",IF(K$2>=$E40,$C40*(1+$G40)^FLOOR((K$2-$E40)/3,1),0),IF(K$2=$E40,$C40,0)) -> 0 | L40: =IF($F40="Recurring",IF(L$2>=$E40,$C40*(1+$G40)^FLOOR((L$2-$E40)/3,1),0),IF(L$2=$E40,$C40,0)) -> 0 | M40: =IF($F40="Recurring",IF(M$2>=$E40,$C40*(1+$G40)^FLOOR((M$2-$E40)/3,1),0),IF(M$2=$E40,$C40,0)) -> 0 | N40: =IF($F40="Recurring",IF(N$2>=$E40,$C40*(1+$G40)^FLOOR((N$2-$E40)/3,1),0),IF(N$2=$E40,$C40,0)) -> 0 | O40: =IF($F40="Recurring",IF(O$2>=$E40,$C40*(1+$G40)^FLOOR((O$2-$E40)/3,1),0),IF(O$2=$E40,$C40,0)) -> 0 | P40: 1 | Q40: 1 | R40: 1 | S40: 1 | T40: 1 | U40: 1 | V40: 1 | W40: 1 | X40: 1 | Y40: 1 | Z40: =SUM(H40:Y40) -> 10
B41: Global Market | C41: 1.5 | D41: RIA registration complete | E41: 12 | F41: Recurring | G41: 0 | H41: =IF($F41="Recurring",IF(H$2>=$E41,$C41*(1+$G41)^FLOOR((H$2-$E41)/3,1),0),IF(H$2=$E41,$C41,0)) -> 0 | I41: =IF($F41="Recurring",IF(I$2>=$E41,$C41*(1+$G41)^FLOOR((I$2-$E41)/3,1),0),IF(I$2=$E41,$C41,0)) -> 0 | J41: =IF($F41="Recurring",IF(J$2>=$E41,$C41*(1+$G41)^FLOOR((J$2-$E41)/3,1),0),IF(J$2=$E41,$C41,0)) -> 0 | K41: =IF($F41="Recurring",IF(K$2>=$E41,$C41*(1+$G41)^FLOOR((K$2-$E41)/3,1),0),IF(K$2=$E41,$C41,0)) -> 0 | L41: =IF($F41="Recurring",IF(L$2>=$E41,$C41*(1+$G41)^FLOOR((L$2-$E41)/3,1),0),IF(L$2=$E41,$C41,0)) -> 0 | M41: =IF($F41="Recurring",IF(M$2>=$E41,$C41*(1+$G41)^FLOOR((M$2-$E41)/3,1),0),IF(M$2=$E41,$C41,0)) -> 0 | N41: =IF($F41="Recurring",IF(N$2>=$E41,$C41*(1+$G41)^FLOOR((N$2-$E41)/3,1),0),IF(N$2=$E41,$C41,0)) -> 0 | O41: =IF($F41="Recurring",IF(O$2>=$E41,$C41*(1+$G41)^FLOOR((O$2-$E41)/3,1),0),IF(O$2=$E41,$C41,0)) -> 0 | P41: 0 | Q41: 0 | R41: 0 | S41: 1.5 | T41: 1.5 | U41: 1.5 | V41: 1.5 | W41: 1.5 | X41: 1.5 | Y41: 1.5 | Z41: =SUM(H41:Y41) -> 10.5
B42: Direct equity research | C42: 3 | D42: Phase 1 — first paying users | E42: 3 | F42: Recurring | G42: 0 | H42: =IF($F42="Recurring",IF(H$2>=$E42,$C42*(1+$G42)^FLOOR((H$2-$E42)/3,1),0),IF(H$2=$E42,$C42,0)) -> 0 | I42: =IF($F42="Recurring",IF(I$2>=$E42,$C42*(1+$G42)^FLOOR((I$2-$E42)/3,1),0),IF(I$2=$E42,$C42,0)) -> 0 | J42: 3 | K42: 3 | L42: 3 | M42: 3 | N42: 3 | O42: 3 | P42: 3 | Q42: 3 | R42: 3 | S42: 3 | T42: 3 | U42: 3 | V42: 3 | W42: 3 | X42: 3 | Y42: 3 | Z42: =SUM(H42:Y42) -> 48
...

Sheet Hiring Plan
A1: Nxance — 18-Month Team & Hiring Cost Plan
A3: Role / Cost Pool | B3: Function | C3: Monthly Cost (₹ lakh) | D3: Annualized Cost (₹ lakh) | E3: Start Month | F3: Active Months | G3: 18M Cost (₹ lakh) | H3: Budget Source | I3: Hiring / Activation Logic
A4: Abhishek | B4: Leadership | C4: 1.25 | D4: 15 | E4: 1 | F4: 18 | G4: 22.5 | H4: Budgeting row 5 | I4: Day 1 — company formation
A5: Bhaskar | B5: Leadership | C5: 1.25 | D5: 15 | E5: 1 | F5: 18 | G5: 22.5 | H5: Budgeting row 6 | I5: Day 1 — company formation
A6: Deepesh | B6: Leadership | C6: 1.25 | D6: 15 | E6: 1 | F6: 18 | G6: 22.5 | H6: Budgeting row 7 | I6: Day 1 — company formation
A7: Raghav | B7: Leadership | C7: 1.5 | D7: 18 | E7: 1 | F7: 18 | G7: 27 | H7: Budgeting row 8 | I7: Day 1 — company formation
A8: QA/Test Engineer | B8: Technology | C8: 1 | D8: 12 | E8: 5 | F8: 14 | G8: 14 | H8: Budgeting row 17 | I8: MBP feature-complete, entering test phase
A9: Quant Analyst — Health Check engine | B9: Quant / Research | C9: 1.5 | D9: 18 | E9: 1 | F9: 18 | G9: 27 | H9: Budgeting row 18 | I9: Beta phase begins (post-MBP validation)
A10: Quant Analyst — Construction engine | B10: Quant / Research | C10: 1.5 | D10: 18 | E10: 1 | F10: 18 | G10: 27 | H10: Budgeting row 19 | I10: Beta phase begins (post-MBP validation)
A11: Backend Engineer 1 | B11: Technology | C11: 1 | D11: 12 | E11: 2 | F11: 17 | G11: 17 | H11: Budgeting row 23 | I11: MBP build starts
A12: Backend Engineer 2 | B12: Technology | C12: 1 | D12: 12 | E12: 5 | F12: 14 | G12: 14 | H12: Budgeting row 24 | I12: Beta phase — scaling build capacity
A13: Frontend Engineer | B13: Technology | C13: 1 | D13: 12 | E13: 2 | F13: 17 | G13: 17 | H13: Budgeting row 25 | I13: MBP build starts
A14: ML Engineer | B14: AI/ML | C14: 1 | D14: 12 | E14: 1 | F14: 18 | G14: 18 | H14: Budgeting row 26 | I14: Phase 1 roadmap — scenario sandbox work begins
A15: AI Engineer | B15: AI/ML | C15: 1 | D15: 12 | E15: 1 | F15: 18 | G15: 18 | H15: Budgeting row 27 | I15: Phase 1 roadmap — NxanceLM build-out
... A28: Customer Support (1–2 people) | B28: Customer Success | C28: 0.6 | D28: 7.2 | E28: 3 | F28: 16 | G28: 9.6 | H28: Budgeting row 55 | I28: Beta phase — live users need support
A31: Team Cost & Exit Metrics
A32: Metric | B32: Value | C32: Unit | D32: Interpretation
A33: Budgeted people/team cost pools | B33: =SUM(G4:G28) -> 583.1 | C33: ₹ lakh | D33: Sum of explicit people/team rows above
A34: Exit monthly payroll / team cost | B34: =SUM(Budgeting!Y5,Budgeting!Y6,Budgeting!Y7,Budgeting!Y8,Budgeting!Y17,Budgeting!Y18,Budgeting!Y19,Budgeting!Y23,Budgeting!Y24,Budgeting!Y25,Budgeting!Y26,Budgeting!Y27,Budgeting!Y28,Budgeting!Y30,Budgeting!Y35,Budgeting!Y36,Budgeting!Y37,Budgeting!Y38,Budgeting!Y39,Budgeting!Y41,Budgeting!Y42,Budgeting!Y44,Budgeting!Y45,Budgeting!Y53,Budgeting!Y55) -> 37.85 | C34: ₹ lakh/month | D34: Month 18 explicit people/team cost pools
A35: Exit headcount capacity | B35: =Assumptions!B7 -> 40 | C35: people | D35: Operating capacity assumption from Budgeting
A36: Total cost pools listed | B36: =COUNTA(A4:A28) -> 25 | C36: lines | D36: Number of explicit people/team cost pools

Sheet Assumptions
A1: Nxance — Core Model Assumptions & Controls
A3: Assumption | B3: Base Input | C3: Unit | D3: Purpose / Rationale | E3: Source / Benchmark | F3: Editable?
A4: Runway | B4: 18 | C4: months | D4: Investor budget horizon | E4: Management model | F4: Yes
A5: Contingency | B5: 0.12 | C5: % of operating burn | D5: Applied to operating burn; refundable reserve excluded | E5: Model policy | F5: Yes
A6: Revenue offset in funding ask | B6: 0 | C6: % | D6: Funding ask is gross cash requirement; revenue shown separately | E6: Conservative funding policy | F6: Yes
A7: Exit headcount capacity | B7: 40 | C7: people | D7: Capacity assumption used for email / operating setup | E7: Budgeting — Organization input | F7: Yes
A8: RIA refundable deposit | B8: 5 | C8: ₹ lakh | D8: Tracked as restricted/refundable cash, not ordinary operating burn | E8: Budgeting / regulatory reserve | F8: Yes
A9: Operating location | B9: Bengaluru | C9: city | D9: Primary office cost base in current budget | E9: Budgeting — Organization input | F9: Yes
A10: Budget currency | B10: ₹ lakh | C10: unit | D10: All detailed monthly budget numbers use ₹ lakh | E10: Model convention | F10: No
A11: Founder cash compensation | B11: 1.25 / 1.25 / 1.25 / 1.50 | C11: ₹ lakh/month | D11: Four founder monthly cash draws per current input | E11: Budgeting — Founder section | F11: Yes
A12: Monthly schedule source of truth | B12: Budgeting H:Y | C12: 18-month schedule | D12: Custom ramps (e.g. marketing/compute) preserved as management inputs | E12: Current workbook | F12: Yes
A15: Valuation & Exit Planning Assumptions
A16: Assumption | B16: Base Input | C16: Unit | D16: Purpose / Rationale | E16: Source / Benchmark | F16: Editable?
A17: Target round dilution | B17: 0.2 | C17: % | D17: Planning case for round economics; not a valuation opinion | E17: Model planning input | F17: Yes
A18: Future dilution after current round | B18: 0.35 | C18: % | D18: Illustrative Series A/B + ESOP dilution | E18: Prior Nxance integrated model | F18: Yes
A19: Target investor MOIC | B19: 10 | C19: x | D19: Return hurdle used only for exit requirement sensitivity | E19: Prior Nxance integrated model | F19: Yes
A20: Exit horizon | B20: 5 | C20: years | D20: Used for IRR sensitivity | E20: Model planning input | F20: Yes
A21: Illustrative target exit value | B21: 750 | C21: ₹ crore | D21: Scenario anchor, not forecast | E21: Prior Nxance integrated model | F21: Yes
A22: Prior base-case Year-5 revenue | B22: 62.9 | C22: ₹ crore | D22: Reference operating case retained for valuation cross-check | E22: Prior Nxance integrated model | F22: Yes
A23: Year-5 revenue exit multiple | B23: 6 | C23: x | D23: Cross-check only; separate from funding need | E23: Prior Nxance integrated model | F23: Yes
A26: Model Control Notes
A27: 1 | B27: Budgeting is the primary management input schedule; downstream tabs must link to it.
A28: 2 | B28: Gross subscription revenue is shown in Business model but is not netted against the funding ask.
A29: 3 | B29: Refundable/restricted deposits are included in cash requirement but shown separately from operating burn.
A30: 4 | B30: Valuation and exit tables are scenario tools; the funding requirement does not determine enterprise value.

Sheet Monthly Burn
A1: Nxance — Monthly Cash Burn & Runway (₹ lakh)
A3: Month | B3: Founder / Leadership | C3: Insurance | D3: Technology | E3: Investment & Research | F3: Marketing & Branding | G3: Sales | H3: Organization | I3: Compliance & License | J3: Operating Burn (excl. reserve) | K3: Reserve / Refundable | L3: Total Cash Use | M3: Cumulative Cash Use | N3: Revenue Offset | O3: Net Cash Burn | P3: Cumulative Net Burn
A4: 1 | B4: =SUM(Budgeting!H5:H8) -> 5.25 | C4: =SUM(Budgeting!H11:H13) -> 0 | D4: =SUM(Budgeting!H16:H31) -> 8.5 | E4: =SUM(Budgeting!H35:H45) -> 0 | F4: =SUM(Budgeting!H48:H50) -> 6 | G4: =SUM(Budgeting!H53:H56) -> 0 | H4: =SUM(Budgeting!H59:H68) -> 5.65 | I4: =SUM(Budgeting!H71:H80) -> 2.2 | J4: =SUM(B4:I4) -> 27.6 | K4: =Budgeting!H84 -> 0 | L4: =J4+K4 -> 27.6 | M4: =SUM($L$4:L4) -> 27.6 | N4: =Assumptions!B6 -> 0 | O4: =L4-N4 -> 27.6 | P4: =SUM($O$4:O4) -> 27.6
A5: 2 | B5: =SUM(Budgeting!I5:I8) -> 5.25 | C5: =SUM(Budgeting!I11:I13) -> 0 | D5: =SUM(Budgeting!I16:I31) -> 14.5 | E5: =SUM(Budgeting!I35:I45) -> 0 | F5: =SUM(Budgeting!I48:I50) -> 6 | G5: =SUM(Budgeting!I53:I56) -> 2.5 | H5: =SUM(Budgeting!I59:I68) -> 4.15 | I5: =SUM(Budgeting!I71:I80) -> 1.5 | J5: =SUM(B5:I5) -> 33.9 | K5: =Budgeting!I84 -> 0 | L5: =J5+K5 -> 33.9 | M5: =SUM($L$4:L5) -> 61.5 | N5: =Assumptions!B6 -> 0 | O5: =L5-N5 -> 33.9 | P5: =SUM($O$4:O5) -> 61.5
A6: 3 | B6: =SUM(Budgeting!J5:J8) -> 5.25 | C6: =SUM(Budgeting!J11:J13) -> 0.3 | D6: =SUM(Budgeting!J16:J31) -> 14.5 | E6: =SUM(Budgeting!J35:J45) -> 13.5 | F6: =SUM(Budgeting!J48:J50) -> 7 | G6: =SUM(Budgeting!J53:J56) -> 3.1 | H6: =SUM(Budgeting!J59:J68) -> 4.15 | I6: =SUM(Budgeting!J71:J80) -> 1.45 | J6: =SUM(B6:I6) -> 49.25 | K6: =Budgeting!J84 -> 0 | L6: =J6+K6 -> 49.25 | M6: =SUM($L$4:L6) -> 110.75 | N6: =Assumptions!B6 -> 0 | O6: =L6-N6 -> 49.25 | P6: =SUM($O$4:O6) -> 110.75
A7: 4 | B7: =SUM(Budgeting!K5:K8) -> 5.25 | C7: =SUM(Budgeting!K11:K13) -> 0.3 | D7: =SUM(Budgeting!K16:K31) -> 14.62 | E7: =SUM(Budgeting!K35:K45) -> 13.5 | F7: =SUM(Budgeting!K48:K50) -> 7.2 | G7: =SUM(Budgeting!K53:K56) -> 3.1 | H7: =SUM(Budgeting!K59:K68) -> 4.15 | I7: =SUM(Budgeting!K71:K80) -> 1.45 | J7: =SUM(B7:I7) -> 49.57 | K7: =Budgeting!K84 -> 0 | L7: =J7+K7 -> 49.57 | M7: =SUM($L$4:L7) -> 160.32 | N7: =Assumptions!B6 -> 0 | O7: =L7-N7 -> 49.57 | P7: =SUM($O$4:O7) -> 160.32
A8: 5 | B8: =SUM(Budgeting!L5:L8) -> 5.25 | C8: =SUM(Budgeting!L11:L13) -> 0.3 | D8: =SUM(Budgeting!L16:L31) -> 17.62 | E8: =SUM(Budgeting!L35:L45) -> 15.5 | F8: =SUM(Budgeting!L48:L50) -> 7.42 | G8: =SUM(Budgeting!L53:L56) -> 3.1 | H8: =SUM(Budgeting!L59:L68) -> 4.15 | I8: =SUM(Budgeting!L71:L80) -> 3.45 | J8: =SUM(B8:I8) -> 56.79 | K8: =Budgeting!L84 -> 0 | L8: =J8+K8 -> 56.79 | M8: =SUM($L$4:L8) -> 217.11 | N8: =Assumptions!B6 -> 0 | O8: =L8-N8 -> 56.79 | P8: =SUM($O$4:O8) -> 217.11
A9: 6 | B9: =SUM(Budgeting!M5:M8) -> 5.25 | C9: =SUM(Budgeting!M11:M13) -> 0.3 | D9: =SUM(Budgeting!M16:M31) -> 19.62 | E9: =SUM(Budgeting!M35:M45) -> 15.5 | F9: =SUM(Budgeting!M48:M50) -> 7.662 | G9: =SUM(Budgeting!M53:M56) -> 3.1 | H9: =SUM(Budgeting!M59:M68) -> 4.15 | I9: =SUM(Budgeting!M71:M80) -> 1.45 | J9: =SUM(B9:I9) -> 57.032 | K9: =Budgeting!M84 -> 0 | L9: =J9+K9 -> 57.032 | M9: =SUM($L$4:L9) -> 274.142 | N9: =Assumptions!B6 -> 0 | O9: =L9-N9 -> 57.032 | P9: =SUM($O$4:O9) -> 274.142
A10: 7 | B10: =SUM(Budgeting!N5:N8) -> 5.25 | C10: =SUM(Budgeting!N11:N13) -> 0.3 | D10: =SUM(Budgeting!N16:N31) -> 19.75 | E10: =SUM(Budgeting!N35:N45) -> 15.5 | F10: =SUM(Budgeting!N48:N50) -> 9.9282 | G10: =SUM(Budgeting!N53:N56) -> 3.1 | H10: =SUM(Budgeting!N59:N68) -> 4.15 | I10: =SUM(Budgeting!N71:N80) -> 1.7 | J10: =SUM(B10:I10) -> 59.6782 | K10: =Budgeting!N84 -> 5 | L10: =J10+K10 -> 64.6782 | M10: =SUM($L$4:L10) -> 338.8202 | N10: =Assumptions!B6 -> 0 | O10: =L10-N10 -> 64.6782 | P10: =SUM($O$4:O10) -> 338.8202
A11: 8 | B11: =SUM(Budgeting!O5:O8) -> 5.25 | C11: =SUM(Budgeting!O11:O13) -> 0.3 | D11: =SUM(Budgeting!O16:O31) -> 19.75 | E11: =SUM(Budgeting!O35:O45) -> 15.5 | F11: =SUM(Budgeting!O48:O50) -> 10.22102 | G11: =SUM(Budgeting!O53:O56) -> 3.1 | H11: =SUM(Budgeting!O59:O68) -> 4.15 | I11: =SUM(Budgeting!O71:O80) -> 1.45 | J11: =SUM(B11:I11) -> 59.72102 | K11: =Budgeting!O84 -> 0 | L11: =J11+K11 -> 59.72102 | M11: =SUM($L$4:L11) -> 398.54122 | N11: =Assumptions!B6 -> 0 | O11: =L11-N11 -> 59.72102 | P11: =SUM($O$4:O11) -> 398.54122
A12: 9 | B12: =SUM(Budgeting!P5:P8) -> 5.25 | C12: =SUM(Budgeting!P11:P13) -> 0.3 | D12: =SUM(Budgeting!P16:P31) -> 20.75 | E12: =SUM(Budgeting!P35:P45) -> 19.5 | F12: =SUM(Budgeting!P48:P50) -> 11.543122 | G12: =SUM(Budgeting!P53:P56) -> 3.1 | H12: =SUM(Budgeting!P59:P68) -> 4.15 | I12: =SUM(Budgeting!P71:P80) -> 1.45 | J12: =SUM(B12:I12) -> 66.043122 | K12: =Budgeting!P84 -> 0 | L12: =J12+K12 -> 66.043122 | M12: =SUM($L$4:L12) -> 464.58434 | N12: =Assumptions!B6 -> 0 | O12: =L12-N12 -> 66.043122 | P12: =SUM($O$4:O12) -> 464.58434
A13: 10 | B13: =SUM(Budgeting!Q5:Q8) -> 5.25 | C13: =SUM(Budgeting!Q11:Q13) -> 0.3 | D13: =SUM(Budgeting!Q16:Q31) -> 21.2 | E13: =SUM(Budgeting!Q35:Q45) -> 19.5 | F13: =SUM(Budgeting!Q48:Q50) -> 11.897434 | G13: =SUM(Budgeting!Q53:Q56) -> 3.1 | H13: =SUM(Budgeting!Q59:Q68) -> 4.15 | I13: =SUM(Budgeting!Q71:Q80) -> 1.45 | J13: =SUM(B13:I13) -> 66.847434 | K13: =Budgeting!Q84 -> 0 | L13: =J13+K13 -> 66.847434 | M13: =SUM($L$4:L13) -> 531.43178 | N13: =Assumptions!B6 -> 0 | O13: =L13-N13 -> 66.847434 | P13: =SUM($O$4:O13) -> 531.43178
A14: 11 | B14: =SUM(Budgeting!R5:R8) -> 5.25 | C14: =SUM(Budgeting!R11:R13) -> 0.3 | D14: =SUM(Budgeting!R16:R31) -> 21.2 | E14: =SUM(Budgeting!R35:R45) -> 19.5 | F14: =SUM(Budgeting!R48:R50) -> 12.287178 | G14: =SUM(Budgeting!R53:R56) -> 3.1 | H14: =SUM(Budgeting!R59:R68) -> 4.15 | I14: =SUM(Budgeting!R71:R80) -> 1.45 | J14: =SUM(B14:I14) -> 67.237178 | K14: =Budgeting!R84 -> 0 | L14: =J14+K14 -> 67.237178 | M14: =SUM($L$4:L14) -> 598.66895 | N14: =Assumptions!B6 -> 0 | O14: =L14-N14 -> 67.237178 | P14: =SUM($O$4:O14) -> 598.66895
A15: 12 | B15: =SUM(Budgeting!S5:S8) -> 5.25 | C15: =SUM(Budgeting!S11:S13) -> 0.3 | D15: =SUM(Budgeting!S16:S31) -> 21.2 | E15: =SUM(Budgeting!S35:S45) -> 21 | F15: =SUM(Budgeting!S48:S50) -> 12.715895 | G15: =SUM(Budgeting!S53:S56) -> 3.1 | H15: =SUM(Budgeting!S59:S68) -> 4.15 | I15: =SUM(Budgeting!S71:S80) -> 1.45 | J15: =SUM(B15:I15) -> 69.165895 | K15: =Budgeting!S84 -> 0 | L15: =J15+K15 -> 69.165895 | M15: =SUM($L$4:L15) -> 667.83485 | N15: =Assumptions!B6 -> 0 | O15: =L15-N15 -> 69.165895 | P15: =SUM($O$4:O15) -> 667.83485
A16: 13 | B16: =SUM(Budgeting!T5:T8) -> 5.25 | C16: =SUM(Budgeting!T11:T13) -> 0.3 | D16: =SUM(Budgeting!T16:T31) -> 21.72 | E16: =SUM(Budgeting!T35:T45) -> 21 | F16: =SUM(Budgeting!T48:T50) -> 15.187485 | G16: =SUM(Budgeting!T53:T56) -> 3.1 | H16: =SUM(Budgeting!T59:T68) -> 4.15 | I16: =SUM(Budgeting!T71:T80) -> 1.45 | J16: =SUM(B16:I16) -> 72.157485 | K16: =Budgeting!T84 -> 0 | L16: =J16+K16 -> 72.157485 | M16: =SUM($L$4:L16) -> 739.99233 | N16: =Assumptions!B6 -> 0 | O16: =L16-N16 -> 72.157485 | P16: =SUM($O$4:O16) -> 739.99233
A17: 14 | B17: =SUM(Budgeting!U5:U8) -> 5.25 | C17: =SUM(Budgeting!U11:U13) -> 0.3 | D17: =SUM(Budgeting!U16:U31) -> 21.72 | E17: =SUM(Budgeting!U35:U45) -> 21 | F17: =SUM(Budgeting!U48:U50) -> 15.706233 | G17: =SUM(Budgeting!U53:U56) -> 3.1 | H17: =SUM(Budgeting!U59:U68) -> 4.15 | I17: =SUM(Budgeting!U71:U80) -> 1.45 | J17: =SUM(B17:I17) -> 72.676233 | K17: =Budgeting!U84 -> 0 | L17: =J17+K17 -> 72.676233 | M17: =SUM($L$4:L17) -> 812.66857 | N17: =Assumptions!B6 -> 0 | O17: =L17-N17 -> 72.676233 | P17: =SUM($O$4:O17) -> 812.66857
A18: 15 | B18: =SUM(Budgeting!V5:V8) -> 5.25 | C18: =SUM(Budgeting!V11:V13) -> 0.3 | D18: =SUM(Budgeting!V16:V31) -> 21.72 | E18: =SUM(Budgeting!V35:V45) -> 21 | F18: =SUM(Budgeting!V48:V50) -> 17.276857 | G18: =SUM(Budgeting!V53:V56) -> 3.1 | H18: =SUM(Budgeting!V59:V68) -> 4.15 | I18: =SUM(Budgeting!V71:V80) -> 1.45 | J18: =SUM(B18:I18) -> 74.246857 | K18: =Budgeting!V84 -> 0 | L18: =J18+K18 -> 74.246857 | M18: =SUM($L$4:L18) -> 886.91542 | N18: =Assumptions!B6 -> 0 | O18: =L18-N18 -> 74.246857 | P18: =SUM($O$4:O18) -> 886.91542
A19: 16 | B19: =SUM(Budgeting!W5:W8) -> 5.25 | C19: =SUM(Budgeting!W11:W13) -> 0.3 | D19: =SUM(Budgeting!W16:W31) -> 22.31 | E19: =SUM(Budgeting!W35:W45) -> 21 | F19: =SUM(Budgeting!W48:W50) -> 17.904542 | G19: =SUM(Budgeting!W53:W56) -> 3.1 | H19: =SUM(Budgeting!W59:W68) -> 4.15 | I19: =SUM(Budgeting!W71:W80) -> 1.45 | J19: =SUM(B19:I19) -> 75.464542 | K19: =Budgeting!W84 -> 0 | L19: =J19+K19 -> 75.464542 | M19: =SUM($L$4:L19) -> 962.37997 | N19: =Assumptions!B6 -> 0 | O19: =L19-N19 -> 75.464542 | P19: =SUM($O$4:O19) -> 962.37997
A20: 17 | B20: =SUM(Budgeting!X5:X8) -> 5.25 | C20: =SUM(Budgeting!X11:X13) -> 0.3 | D20: =SUM(Budgeting!X16:X31) -> 22.31 | E20: =SUM(Budgeting!X35:X45) -> 21 | F20: =SUM(Budgeting!X48:X50) -> 18.594997 | G20: =SUM(Budgeting!X53:X56) -> 3.1 | H20: =SUM(Budgeting!X59:X68) -> 4.15 | I20: =SUM(Budgeting!X71:X80) -> 1.45 | J20: =SUM(B20:I20) -> 76.154997 | K20: =Budgeting!X84 -> 0 | L20: =J20+K20 -> 76.154997 | M20: =SUM($L$4:L20) -> 1038.535 | N20: =Assumptions!B6 -> 0 | O20: =L20-N20 -> 76.154997 | P20: =SUM($O$4:O20) -> 1038.535
A21: 18 | B21: =SUM(Budgeting!Y5:Y8) -> 5.25 | C21: =SUM(Budgeting!Y11:Y13) -> 0.3 | D21: =SUM(Budgeting!Y16:Y31) -> 22.31 | E21: =SUM(Budgeting!Y35:Y45) -> 21 | F21: =SUM(Budgeting!Y48:Y50) -> 19.354496 | G21: =SUM(Budgeting!Y53:Y56) -> 3.1 | H21: =SUM(Budgeting!Y59:Y68) -> 4.15 | I21: =SUM(Budgeting!Y71:Y80) -> 1.45 | J21: =SUM(B21:I21) -> 76.914496 | K21: =Budgeting!Y84 -> 0 | L21: =J21+K21 -> 76.914496 | M21: =SUM($L$4:L21) -> 1115.4495 | N21: =Assumptions!B6 -> 0 | O21: =L21-N21 -> 76.914496 | P21: =SUM($O$4:O21) -> 1115.4495
A24: 18-Month Funding Metrics
A25: Metric | B25: Value | C25: Unit | D25: Interpretation
A26: Operating burn — excluding refundable reserve | B26: =SUM(J4:J21) -> 1110.4495 | C26: ₹ lakh | D26: 18-month operating cash requirement
A27: Refundable / restricted reserve | B27: =SUM(K4:K21) -> 5 | C27: ₹ lakh | D27: SEBI RIA deposit tracked separately
A28: Contingency | B28: =B26*Assumptions!B5 -> 133.25394 | C28: ₹ lakh | D28: 12% of operating burn
A29: Recommended funding ask | B29: =SUM(B26:B28) -> 1248.7034 | C29: ₹ lakh | D29: Operating burn + reserve + contingency
A30: Recommended funding ask | B30: =B29/100 -> 12.487034 | C30: ₹ crore | D30: Investor-facing amount
A31: Average monthly cash use | B31: =AVERAGE(L4:L21) -> 61.969414 | C31: ₹ lakh/month | D31: Before contingency
A32: Peak monthly cash use | B32: =MAX(L4:L21) -> 76.914496 | C32: ₹ lakh/month | D32: Before contingency

Sheet Use of Fund
A1: Nxance — Investor Use of Funds (18-Month Base Case)
A3: Category | B3: Amount (₹ lakh) | C3: Amount (₹ crore) | D3: % of Ask | E3: What It Funds | F3: Investor Rationale
A4: Founder / leadership | B4: =Budgeting!AA9 -> 94.5 | C4: =B4/100 -> 0.945 | D4: =B4/$B$17 -> 0.0756785 | E4: Four founder cash draws across the full runway | F4: Maintains founder focus while keeping cash compensation transparent
A5: Insurance | B5: =Budgeting!AA14 -> 4.8 | C5: =B5/100 -> 0.048 | D5: =B5/$B$17 -> 0.0038439873 | E5: D&O, cyber liability and general liability | F5: Protects the company and management against operating risk
A6: Technology & AI | B6: =Budgeting!AA33 -> 345.3 | C6: =B6/100 -> 3.453 | D6: =B6/$B$17 -> 0.27652684 | E6: Cloud, AI/LLM, APIs, engineering, DevOps, tools and compute | F6: Funds the core product and production infrastructure
A7: Investment & research | B7: =Budgeting!AA46 -> 294.5 | C7: =B7/100 -> 2.945 | D7: =B7/$B$17 -> 0.23584464 | E7: Quant, portfolio, research, risk, market and compliance expertise | F7: Builds financial-intelligence depth and human review capability
A8: Marketing & branding | B8: =Budgeting!AA51 -> 213.89946 | C8: =B8/100 -> 2.1389946 | D8: =B8/$B$17 -> 0.17129725 | E8: Social, ads and media ramp | F8: Funds demand generation and brand formation
A9: Sales & customer support | B9: =Budgeting!AA57 -> 52.1 | C9: =B9/100 -> 0.521 | D9: =B9/$B$17 -> 0.041723279 | E9: Ground/call team and customer support | F9: Creates conversion, onboarding and feedback loops
A10: Organization & office | B10: =Budgeting!AA69 -> 76.2 | C10: =B10/100 -> 0.762 | D10: =B10/$B$17 -> 0.061023299 | E10: Bengaluru office, email, infra, tools and administration | F10: Supports execution without a large fixed fit-out
A11: Compliance & licence | B11: =Budgeting!AA82 -> 29.15 | C11: =B11/100 -> 0.2915 | D11: =B11/$B$17 -> 0.023344215 | E11: RIA preparation, legal/CS/audit, DPDP, trademark and regulatory buffer | F11: Funds regulated-fintech readiness and governance
A12: Refundable / restricted reserve | B12: =Budgeting!AA84 -> 5 | C12: =B12/100 -> 0.05 | D12: =B12/$B$17 -> 0.0040041534 | E12: SEBI RIA deposit | F12: Included in cash requirement but tracked separately from operating burn
A13: Contingency reserve | B13: ='Monthly Burn'!B28 -> 133.25394 | C13: =B13/100 -> 1.3325394 | D13: =B13/$B$17 -> 0.10671384 | E13: 12% of operating burn | F13: Protects runway from budget variance without overstating base costs
C14: =B14/100 -> 0
A15: Subtotal before contingency | B15: =SUM(B4:B12) -> 1115.4495 | C15: =B15/100 -> 11.154495
A16: Contingency | B16: =B13 -> 133.25394 | C16: =B16/100 -> 1.3325394
A17: Recommended funding ask | B17: =SUM(B15:B16) -> 1248.7034 | C17: =B17/100 -> 12.487034

Sheet Milestone and Regulatory
A1: Product, Regulatory and Funding Milestones
A3: Phase | B3: Months | C3: Product Deliverable | D3: Regulatory / Risk Work | E3: Validation KPI | F3: Key Hires | G3: Budget Release Gate | H3: Investor Evidence
A4: Foundation | B4: 1–3 | C4: Portfolio import, health score, analytics engine and admin QA | D4: Legal opinion on analytics vs RA vs IA; privacy map; AI disclosure design | E4: 100 interviews; 30–50 active testers | F4: CTO, engineers, ML, quant, product | G4: Release alpha build budget | H4: Working demo and documented pain points
A5: Alpha | B5: 4–6 | C5: Risk profile, suitability workflow, Monte Carlo and human review | D5: SEBI readiness/application path; KYC design; first VAPT; incident plan | E5: 100+ completed analyses; 40% repeat usage | F5: QA, DevOps/security, compliance | G5: Release closed-beta budget | H5: Controls, audit trail and adviser workflow
A6: Closed Beta | B6: 7–9 | C6: Payments, recommendations, model monitoring and support workflows | D6: Client agreements, record keeping, AI-use disclosures and data licences | E6: 300–500 users; 25–50 paying users | F6: 2nd backend and ML engineer | G6: Release public-launch budget | H6: Retention, paid conversion and support data
A7: Public V1 | B7: 10–12 | C7: Scalable production product, portfolio monitoring and reports | D7: Production VAPT; vendor reviews; complaints and audit processes | E7: 1,000+ users; early recurring revenue | F7: 2nd customer success | G7: Release simulation phase | H7: Revenue quality and operating resilience
A8: Simulation Alpha | B8: 13–15 | C8: Market replay, synthetic scenarios, behavioural agents and stress tests | D8: Model-risk framework, scenario validation and explainability | E8: 2 design partners; validated scenario library | F8: Simulation scientist | G8: Release institutional-pilot budget | H8: Technical differentiation and enterprise demand
A9: Institutional Scale | B9: 16–18 | C9: Advisor + simulation platform, APIs and enterprise dashboards | D9: ISO/SOC readiness, advanced security review, policy refresh | E9: 3 institutional pilots; 5,000 users target | F9: Existing team scales operations | G9: Prepare next round | H9: Pilot LOIs, revenue and governance maturity
A12: Regulatory Product Boundary — Budget Implication
A14: Product Mode | B14: Likely Regulatory Track | C14: What the Product Can Do | D14: What Changes in Budget | E14: Key Control | F14: Go-Live Condition | G14: Owner | H14: Note
A15: Analytics-only | B15: Lower-regulatory product layer | C15: Historical analysis, risk metrics and general education without personalised buy/sell advice | D15: Can launch earlier; still needs privacy, security and data licences | E15: Clear non-advisory boundaries | F15: External legal opinion | G15: Founder + counsel | H15: Do not rely only on disclaimers
A16: Research recommendations | B16: SEBI Research Analyst path may apply | C16: Security-specific research/recommendations or model portfolios | D16: RA registration, certifications, records and disclosures | E16: Research methodology and conflict controls | F16: Registration/readiness confirmation | G16: Compliance lead | H16: AI use must be transparently disclosed
A17: Personalised advice | B17: SEBI Investment Adviser path likely applies | C17: Advice tailored to client goals, risk and portfolio | D17: RIA application, deposit, KYC, risk profiling, suitability, agreements and records | E17: Fiduciary/human accountability | F17: Registration and operating controls | G17: Principal officer + compliance | H17: Core advisory/compliance cannot be outsourced
A18: Execution / brokerage integration | B18: Additional partner and regulatory dependencies | C18: Implementation, account aggregation, execution or brokerage-linked workflows | D18: Partner integration, due diligence and stronger controls | E18: Client consent and activity segregation | F18: Approved regulated partner model | G18: CEO + compliance | H18: Treat as a later phase

Sheet Funding Tranches
A1: PHASED FUNDING STRUCTURE — ₹12.49 Cr / 20.00% Equity / 18 Months
A2: Capital and equity are released together, tranche by tranche, only once the linked milestone/gate is met (see 'Investor Decision Gates' tab)
A3: Tranche / Gate | B3: Period | C3: Months | D3: Capital (₹ L) | E3: Capital (₹L/month) | F3: Equity this tranche | G3: Cumulative capital (₹ L) | H3: Cumulative equity | I3: Key deliverables (unlocks the tranche)
A4: Tranche 1 | B4: Month 1–6 | C4: 6 | D4: 274.14 | E4: =D4/C4 -> 45.69 | F4: 0.06 | G4: =SUM($D$4:D4) -> 274.14 | H4: =SUM($F$4:F4) -> 0.06 | I4: Legal foundation live + MBP fully built across all 3 engines. Pvt Ltd registration, ESOP pool, founder/core payroll active, Number Guard live from Day 1, MBP feature-complete, core team hired.
A5: Tranche 2 | B5: Month 7–12 | C5: 6 | D5: 527.24 | E5: =D5/C5 -> 87.873333 | F5: 0.07 | G5: =SUM($D$4:D5) -> 801.38 | H5: =SUM($F$4:F5) -> 0.13 | I5: Open beta live; MBP converts toward SEBI-RIA readiness. Legal/compliance consultant onboard, VAPT + data-security plan executed, SEBI-RIA application filed, beta feature build (construction/tracking hardening). Established run-rate with recurring revenue, institutional pilots and security maturity.
A6: Tranche 3 | B6: Month 13–18 | C6: 6 | D6: 447.62 | E6: =D6/C6 -> 74.603333 | F6: 0.07 | G6: =SUM($D$4:D6) -> 1249 | H6: =SUM($F$4:F6) -> 0.2 | I6: SEBI-RIA registration secured; paid conversion, repeat-use and support data validated. ML/AI/Cybersecurity engineers onboard, Phase-1 roadmap (Gold, ETF) underway. Full team run-rate, growth channels (marketing, distributor), compliance filings and statutory audit complete, next financing/strategic path prepared.
A8: TOTAL (Round, if fully drawn) | C8: =SUM(C4:C6) -> 18 | D8: =SUM(D4:D6) -> 1249 | F8: =SUM(F4:F6) -> 0.2 | G8: =D8 -> 1249 | H8: =F8 -> 0.2

Sheet valuation
A1: Nxance — Valuation & Dilution Scenario Framework
A3: Selected Round Economics | F3: Dilution / Valuation Sensitivity
A4: Input / Output | B4: Value | C4: Unit | D4: Rationale | F4: Round Dilution | G4: Pre-Money (₹ crore) | H4: Post-Money (₹ crore) | I4: Exit Ownership after Future Dilution | J4: Required Exit for 10x (₹ crore)
A5: Recommended funding ask | B5: ='Monthly Burn'!B30 -> 12.487034 | C5: ₹ crore | D5: Linked to 18-month funding model | F5: 0.15 | G5: =$B$5*(1-F5)/F5 -> 70.759859 | H5: =$B$5/F5 -> 83.246893 | I5: =F5*(1-$B$9) -> 0.0975 | J5: =$B$5*$B$11/I5 -> 1280.7214
A6: Target round dilution | B6: =Assumptions!B17 -> 0.2 | C6: % | D6: Editable planning case; not a valuation opinion | F6: 0.2 | G6: =$B$5*(1-F6)/F6 -> 49.948136 | H6: =$B$5/F6 -> 62.43517 | I6: =F6*(1-$B$9) -> 0.13 | J6: =$B$5*$B$11/I6 -> 960.54107
A7: Implied pre-money valuation | B7: =B5*(1-B6)/B6 -> 49.948136 | C7: ₹ crore | D7: Ask × (1-dilution) ÷ dilution | F7: 0.25 | G7: =$B$5*(1-F7)/F7 -> 37.461102 | H7: =$B$5/F7 -> 49.948136 | I7: =F7*(1-$B$9) -> 0.1625 | J7: =$B$5*$B$11/I7 -> 768.43286
A8: Implied post-money valuation | B8: =B5/B6 -> 62.43517 | C8: ₹ crore | D8: Ask ÷ dilution | F8: 0.3 | G8: =$B$5*(1-F8)/F8 -> 29.136413 | H8: =$B$5/F8 -> 41.623447 | I8: =F8*(1-$B$9) -> 0.195 | J8: =$B$5*$B$11/I8 -> 640.36072
A9: Future dilution after this round | B9: =Assumptions!B18 -> 0.35 | C9: % | D9: Series A/B + ESOP sensitivity
A10: Investor ownership at exit | B10: =B6*(1-B9) -> 0.13 | C10: % | D10: Initial ownership retained after future dilution
A11: Target investor MOIC | B11: =Assumptions!B19 -> 10 | C11: x | D11: Exit return hurdle for sensitivity only
A12: Illustrative target exit value | B12: =Assumptions!B21 -> 750 | C12: ₹ crore | D12: Scenario anchor
A13: Exit value required for target MOIC | B13: =B5*B11/B10 -> 960.54107 | C13: ₹ crore | D13: Investment × target MOIC ÷ exit ownership
A16: Year-5 Revenue Cross-Check
A17: Metric | B17: Value | C17: Unit | D17: Interpretation | F17: Investor Return Cross-Check
A18: Prior base-case Year-5 revenue | B18: =Assumptions!B22 -> 62.9 | C18: ₹ crore | D18: Reference from earlier integrated operating model | F18: Exit Value (₹ crore) | G18: Investor Proceeds (₹ crore) | H18: MOIC | I18: 5Y IRR | J18: Interpretation
A19: Exit multiple cross-check | B19: =Assumptions!B23 -> 6 | C19: x | D19: Illustrative revenue multiple | F19: =B20 -> 377.4 | G19: =F19*$B$10 -> 49.062 | H19: =G19/$B$5 -> 3.9290355 | I19: =H19^(1/Assumptions!B20)-1 -> 0.31479242 | J19: 6x Year-5 revenue cross-check
A20: Implied exit value at selected multiple | B20: =B18*B19 -> 377.4 | C20: ₹ crore | D20: Year-5 revenue × multiple | F20: =B12 -> 750 | G20: =F20*$B$10 -> 97.5 | H20: =G20/$B$5 -> 7.8080992 | I20: =H20^(1/Assumptions!B20)-1 -> 0.50837409 | J20: Illustrative target exit
A21: Revenue multiple required for target exit | B21: =$B$12/B18 -> 11.923688 | C21: x | D21: Target exit ÷ Year-5 revenue | F21: =B13 -> 960.54107 | G21: =F21*$B$10 -> 124.87034 | H21: =G21/$B$5 -> 10 | I21: =H21^(1/Assumptions!B20)-1 -> 0.58489319 | J21: Required exit for target MOIC

Sheet Business model
A1: Nxance — Revenue Model & Subscription Economics
A3: Subscription Pricing
A4: Tier | B4: Price / Month (₹) | C4: Price / Year (₹) | D4: What's included
A5: One-Time unlock | B5: ₹99 one-time | C5: - | D5: Full Health Check report unlock — MBP success-gate funnel qualifier, not a plan
A6: Plan 1 — Starter | B6: 399 | C6: 3990 | D6: 2 portfolios; Health Check + Construction; 7–8 sub-engines; limited NxanceLM; monthly auto re-check
A7: Plan 2 — Growth | B7: 899 | C7: 8990 | D7: 2–5 portfolios; 10–15 sub-engines; deep re-check; rebalancing nudges; execution; priority queue
A8: Plan 3 — Pro | B8: 1499 | C8: 14990 | D8: 5–10 portfolios; all 26+ sub-engines; unlimited NxanceLM; fastest queue; priority support; early access
A11: 18-Month Revenue Milestones
A12: Milestone | B12: Period | C12: Paying Subscribers (end of period) | D12: Est. Revenue Collected in Block (₹ lakh)
A13: Milestone 1 | B13: Months 1–5 | C13: 75 | D13: 1.61
A14: Milestone 2 | B14: Months 6–12 | C14: 600 | D14: 14.46
A15: Milestone 3 | B15: Months 13–18 | C15: 2200 | D15: 59.98
A16: TOTAL estimated subscription revenue | D16: =SUM(D13:D15) -> 76.05
A17: 18M operating burn — excluding refundable reserve | D17: ='Monthly Burn'!B26 -> 1110.4495
A18: Revenue as % of operating burn | D18: =D16/D17 -> 0.068485782
A19: Recommended funding ask | D19: ='Monthly Burn'!B29/100 -> 12.487034
A20: Revenue as % of funding ask | D20: =(D16/100)/D19 -> 0.060903174
A21: Funding policy | D21: Revenue is shown as upside and is not netted against the investor ask.

Sheet Exit Plan
A1: Nxance — Exit Plan & Investor Return Scenarios
A3: Exit Inputs | H3: Required Exit by Target Return
A4: Input | B4: Value | C4: Unit | D4: Notes | H4: Target MOIC | I4: Required Exit (₹ crore) | J4: 5Y IRR
A5: Current investment | B5: =valuation!B5 -> 12.487034 | C5: ₹ crore | D5: Recommended funding ask | H5: 3 | I5: =$B$5*H5/$B$8 -> 288.16232 | J5: =H5^(1/$B$9)-1 -> 0.24573094
A6: Initial investor ownership | B6: =valuation!B6 -> 0.2 | C6: % | D6: Planning case from valuation tab | H6: 5 | I6: =$B$5*H6/$B$8 -> 480.27054 | J6: =H6^(1/$B$9)-1 -> 0.37972966
A7: Future dilution | B7: =valuation!B9 -> 0.35 | C7: % | D7: Illustrative later-round + ESOP dilution | H7: 8 | I7: =$B$5*H7/$B$8 -> 768.43286 | J7: =H7^(1/$B$9)-1 -> 0.51571657
A8: Final investor ownership at exit | B8: =valuation!B10 -> 0.13 | C8: % | D8: Initial ownership × retained percentage | H8: 10 | I8: =$B$5*H8/$B$8 -> 960.54107 | J8: =H8^(1/$B$9)-1 -> 0.58489319
A9: Exit horizon | B9: =Assumptions!B20 -> 5 | C9: years | D9: Used for IRR calculations
A10: Target MOIC | B10: =valuation!B11 -> 10 | C10: x | D10: Return sensitivity target
A13: Exit Value Sensitivity
A14: Exit Value (₹ crore) | B14: Investor Proceeds (₹ crore) | C14: MOIC | D14: 5Y IRR | E14: Founder / Other Holder Value (₹ crore) | F14: Interpretation
A15: 250 | B15: =A15*$B$8 -> 32.5 | C15: =B15/$B$5 -> 2.6026997 | D15: =C15^(1/$B$9)-1 -> 0.21083458 | E15: =A15-B15 -> 217.5 | F15: Sub-scale strategic outcome
A16: 500 | B16: =A16*$B$8 -> 65 | C16: =B16/$B$5 -> 5.2053995 | D16: =C16^(1/$B$9)-1 -> 0.39088368 | E16: =A16-B16 -> 435 | F16: Strong strategic outcome
A17: 750 | B17: =A17*$B$8 -> 97.5 | C17: =B17/$B$5 -> 7.8080992 | D17: =C17^(1/$B$9)-1 -> 0.50837409 | E17: =A17-B17 -> 652.5 | F17: Illustrative target case
A18: 1000 | B18: =A18*$B$8 -> 130 | C18: =B18/$B$5 -> 10.410799 | D18: =C18^(1/$B$9)-1 -> 0.5977058 | E18: =A18-B18 -> 870 | F18: High-quality category outcome
A19: 1500 | B19: =A19*$B$8 -> 195 | C19: =B19/$B$5 -> 15.616198 | D19: =C19^(1/$B$9)-1 -> 0.73266684 | E19: =A19-B19 -> 1305 | F19: Exceptional outcome
A22: Strategic Exit Routes — Management Planning Framework
A23: Route | B23: Illustrative Horizon | C23: What Needs to Be True | D23: Evidence to Build | E23: Primary Risk
A24: Strategic acquisition by wealth / fintech platform | B24: 3–5 years | C24: Meaningful paying user base, defensible analytics, regulated operating capability | D24: Retention, recurring revenue, integrations, audited controls | E24: Acquirer dependence before product-market fit
A25: Broker / bank / AMC technology acquisition | B25: 4–6 years | C25: Advice/research workflows are reliable, compliant and easy to integrate | D25: Institutional pilots, APIs, data rights, governance | E25: Regulatory scope and integration complexity
A26: Enterprise AI / risk analytics acquisition | B26: 4–7 years | C26: Simulation and portfolio-intelligence engine becomes enterprise-grade | D26: Institutional ARR, scenario IP, security certifications | E26: Long enterprise sales cycles
A27: Independent scale / IPO pathway | B27: 7+ years | C27: Large recurring revenue base, improving profitability and mature governance | D27: Multi-year audited growth, board quality, cash discipline | E27: Capital intensity and execution duration
A29: Note: Exit values are scenario sensitivities, not forecasts. The model is designed to show what ownership, dilution and operating outcomes would be required for different investor return targets.

Sheet Sources
A1: Nxance — Model Sources, Benchmarks & Internal Inputs
A3: Model Area | B3: Input / Benchmark | C3: Source Type | D3: Source / URL | E3: How Used | F3: Update Needed?
A4: Budget | B4: 18-month detailed management schedule | C4: Internal management input | D4: Budgeting tab | E4: Primary source of monthly cash use and category totals | F4: When management changes budget
A5: Revenue | B5: Subscription pricing and 18-month subscriber milestones | C5: Internal management input | D5: Business model tab | E5: Gross revenue illustration; not netted against funding ask | F5: When pricing / traction changes
A6: Regulatory | B6: Investment Adviser FAQ / deposit reference | C6: External regulatory reference | D6: https://www.sebi.gov.in/sebi_data/faqfiles/aug-2025/1755174193178.pdf | E6: Regulatory deposit / readiness reference | F6: Verify before filing / fundraising close
A7: Market data | B7: NSE corporate data subscription benchmark | C7: External market-data benchmark | D7: https://www.nseindia.com/static/market-data/corporate-data-subscription | E7: Evidence that licensed data can be material | F7: Replace with vendor quotations
A8: Valuation | B8: Prior Nxance integrated valuation & dilution model | C8: Internal prior model | D8: Fintech_Integrated_Financial_Valuation_Dilution_Model.xlsx | E8: Future dilution, MOIC, Year-5 revenue and exit-multiple cross-checks | F8: Refresh after traction / term-sheet feedback
A9: Contingency | B9: 12% of operating burn | C9: Internal model policy | D9: Assumptions tab | E9: Runway protection; excludes refundable reserve | F9: Board / investor decision
A10: Headcount | B10: 40-person operating capacity | C10: Internal management input | D10: Budgeting — Organization / Email line | E10: Executive headcount capacity indicator | F10: Replace with HR-approved org chart
A13: Source Control Note: External regulatory and vendor benchmarks should be re-verified before a financing close or regulated launch. Internal management inputs are intentionally kept distinct from external benchmarks.

Sheet Returns & Refunds
A1: Nxance — Refundable / Restricted Cash Tracker
A3: Item | B3: Funding Month | C3: Cash Outflow (₹ lakh) | D3: Accounting / Cash Treatment | E3: Expected Return / Release | F3: Status | G3: Linked Budget Cell | H3: Notes
A4: SEBI RIA deposit | B4: 7 | C4: =Budgeting!Z84 -> 5 | D4: Restricted/refundable cash; excluded from operating burn | E4: TBD / subject to regulatory terms | F4: Planned | G4: Budgeting!Z84 | H4: Track release separately; do not treat as operating expense
A7: Control Metric | B7: Value | C7: Unit | D7: Note
A8: Total restricted / refundable cash | B8: =SUM(C4:C20) -> 5 | C8: ₹ lakh | D8: Linked to all tracker items
A9: Returned / released cash | B9: 0 | C9: ₹ lakh | D9: Update when actually released
A10: Outstanding restricted cash | B10: =B8-B9 -> 5 | C10: ₹ lakh | D10: Total less released
